tests/functional/testcase00/orders.csv
action,order_id,order_side,order_price,order_quantity
place,buy1,buy,101,5
place,buy2,buy,102,10
place,buy3,buy,103,15
place,buy4,buy,104,20
place,buy5,buy,105,25
place,sell1,sell,106,5
place,sell2,sell,105,10
place,sell3,sell,104,15
place,sell4,sell,103,20
place,sell5,sell,102,25
