tests/functional/testcase01/matches.csv
buy_order_id,sell_order_id,order_price,order_quantity
buy2,sell6,105,25
buy2,sell7,105,25
buy6,sell7,105,8
buy6,sell9,105,11
buy6,sell1,110,25 
buy10,sell10,111,10 
buy7,sell10,108,15 
buy11,sell3,115,35
buy11,sell4,118,45 
buy11,sell5,120,20 
buy8,sell11,106,20 
buy9,sell11,104,25 
buy3,sell11,103,30 
