tests/functional/testcase02/matches.csv
buy_order_id,sell_order_id,order_price,order_quantity
buy_order4,sell98_1,99,1
buy_order4,sell98_2,99,1
buy_order4,sell98_3,99,1
buy_order4,sell98_4,99,1
buy_order4,sell98_5,99,1
buy_order4,sell98_6,99,1
buy_order4,sell98_7,99,1
buy_order4,sell98_8,99,1
buy_order10,sell98_9,99,1
buy_order1,sell98_10,98,1
buy_order11,sell_order16,100,33
buy_order6,sell_order18,96,5
buy_order3,sell_order18,94,11
buy_order12,sell_order17,100,23
buy_order12,sell_order7,102,1
buy_order12,sell_order5,103,9
buy_order12,sell_order6,103,10
buy_order12,sell_order9,106,9
buy_order12,sell_order2,107,14
buy_order13,sell_order13,117,3
buy_order13,sell_order14,117,1
buy_order13,sell_order3,118,7
